Workbook

Sheet US Factory Farming Estimates
A1: US Factory Farming Estimates (Animals Alive at Present)
A2: These estimates use the 2017 Census of Agriculture and EPA definitions of CAFOs to estimate the number of US farmed land vertebrates who are in CAFOs ("factory farms").
A3: Last updated: 04/11/2019
A4: USDA Data | G4: Percentile calculations | J4: Total % factory farmed
A5: Sales, Table 30 | C5: Meat chickens | D5: Cutoff ('Cutoff Calculations') | E5: ='Cutoff Calculations'!G10 -> 9375 | G5: Meat chicken calculations | J5: These estimates use the number of animals per farm as the best available proxy for whether the farm is a CAFO with the following premises: (1) All Large sized farms are CAFOs, (2) all Medium sized farms are CAFOs, and (3) for birds, the largest three quarters of Small sized farms are CAFOs, (4) for mammals, the largest half of Small sized farms are CAFOs, and (5) farms are evenly distributed among sizes within each range.
A6: Animals per farm | B6: Total farms | C6: Total animals | D6: Cumulative | E6: Cumulative % | G6: Farms larger than cutoff range | H6: =E9 -> 0.9994237
A7: 1 to 1999 | B7: 17403 | C7: 1848106 | D7: =D8+C7 -> 8889759283 | E7: =D7/$C$16 -> 1 | G7: Farms larger than and including cutoff range | H7: =E8 -> 0.99979211
A8: 2000 to 15999 | B8: 599 | C8: 3275099 | D8: =D9+C8 -> 8887911177 | E8: =D8/$C$16 -> 0.99979211 | G8: Percentile of cutoff in farm size range | H8: =(E5-2000)/(15999-2000) -> 0.52682334
A9: 16000 to 29999 | B9: 93 | C9: 2101310 | D9: =D10+C9 -> 8884636078 | E9: =D9/$C$16 -> 0.9994237 | G9: % of animals above cutoff | H9: =(H6-H7)*H8+H7 -> 0.99959802
A10: 30000 to 59999 | B10: 100 | C10: 4178760 | D10: =D11+C10 -> 8882534768 | E10: =D10/$C$16 -> 0.99918732
A11: 60000 to 99999 | B11: 263 | C11: 20957369 | D11: =D12+C11 -> 8878356008 | E11: =D11/$C$16 -> 0.99871726 | K11: Best Guess
A12: 100000 to 199999 | B12: 1391 | C12: 206319172 | D12: =D13+C12 -> 8857398639 | E12: =D12/$C$16 -> 0.99635978 | J12: Meat chickens | K12: =H9 -> 0.99959802
A13: 200000 to 299999 | B13: 1965 | C13: 479850660 | D13: =D14+C13 -> 8651079467 | E13: =D13/$C$16 -> 0.97315115 | J13: Egg chickens | K13: =H23 -> 0.98222786
A14: 300000 to 499999 | B14: 3726 | C14: 1457192115 | D14: =D15+C14 -> 8171228807 | E14: =D14/$C$16 -> 0.91917324 | J14: Turkeys | K14: =H36 -> 0.99849756
A15: 500000 or more | B15: 7211 | C15: 6714036692 | D15: =D16+C15 -> 6714036692 | E15: =D15/$C$16 -> 0.75525517 | J15: Pigs | K15: =H48 -> 0.98269014
A16: Total sales | B16: 32751 | C16: =SUM(C7:C15) -> 8889759283 | J16: Cows | K16: =H63 -> 0.70363287
A17: Total inventory | C17: 1621400316 | J17: Total land | K17: =((K12*C17)+(K13*C30)+(K14*C42)+(K15*C55)+(K16*C71))/(C17+C30+C42+C55+C71) -> 0.98391144
J18: Total land + fish | K18: =((K12*C17)+(K13*C30)+(K14*C42)+(K15*C55)+(K16*C71)+K24)/(C17+C30+C42+C55+C71+K24) -> 0.98697941
A19: Inventory, Table 30 | C19: Egg-laying hens | D19: Cutoff ('Cutoff Calculations') | E19: ='Cutoff Calculations'!F10 -> 2250 | G19: Egg-laying hen calculations
A20: Animals per farm | B20: Total farms | C20: Total animals | D20: Cumulative | E20: Cumulative % | G20: Farms larger than cutoff range | H20: =E25 -> 0.98087979 | J20: Fish Estimates
A21: 1 to 49 | B21: 202403 | C21: 3260087 | D21: =D22+C21 -> 368241393 | E21: =D21/$C$30 -> 1 | G21: Farms larger than and including cutoff range | H21: =E24 -> 0.98485581 | J21: We lack US census data for fish farm size, but consensus in the field seems to be that virtually all fish farms are factory farms in terms of confinement, disease, and other relevant metrics.
A22: 50 to 99 | B22: 17066 | C22: 1063287 | D22: =D23+C22 -> 364981306 | E22: =D22/$C$30 -> 0.99114688 | G22: Percentile of cutoff in farm size range | H22: =(E19-400)/(3199-400) -> 0.66095034
A23: 100 to 399 | B23: 7871 | C23: 1253342 | D23: =D24+C23 -> 363918019 | E23: =D23/$C$30 -> 0.9882594 | G23: % of animals above cutoff | H23: =(H20-H21)*H22+H21 -> 0.98222786
A24: 400 to 3199 | B24: 1482 | C24: 1464135 | D24: =D25+C24 -> 362664677 | E24: =D24/$C$30 -> 0.98485581 | J24: US fish (see sheet "Fish Estimates"): | K24: ='Fish Estimates'!B74 -> 5.3251071e+08
A25: 3200 to 9999 | B25: 513 | C25: 3499325 | D25: =D26+C25 -> 361200542 | E25: =D25/$C$30 -> 0.98087979
A26: 10000 to 19999 | B26: 1095 | C26: 16185116 | D26: =D27+C26 -> 357701217 | E26: =D26/$C$30 -> 0.97137699 | J26: Confirmatory Calculation
A27: 20000 to 49999 | B27: 1484 | C27: 42059552 | D27: =D28+C27 -> 341516101 | E27: =D27/$C$30 -> 0.92742453 | J27: % total farms accounted for: | K27: =(SUM(B9:B15,B8*H8)+SUM(B25:B29,B24*H22)+SUM(B36:B40,B35*H35)+SUM(B52:B54,B51*H47)+SUM(B66:B70,B65*H62))/SUM(B16,B30,B41,B55,B71) -> 0.15324682
A28: 50000 to 99999 | B28: 266 | C28: 17973810 | D28: =D29+C28 -> 299456549 | E28: =D28/$C$30 -> 0.81320719 | J28: =HYPERLINK("https://web.archive.org/web/20150812024425/http://www.epa.gov/region7/water/cafo/index.htm","EPA 2012: 'CAFOs make up approximately 15 percent of total AFOs'") -> EPA 2012: 'CAFOs make up approximately 15 percent of total AFOs'
A29: 100000 or more | B29: 320 | C29: 281482739 | D29: =D30+C29 -> 281482739 | E29: =D29/$C$30 -> 0.76439733 | J29: This only weakly confirms our choice of cutoffs, which assume all farms above a certain size (per species) are CAFOs, while in reality some non-CAFO farms will be larger than some CAFO farms.
A30: Total inventory | B30: 232500 | C30: =SUM(C21:C29) -> 368241393
A32: Sales, Table 30 | C32: Turkeys | D32: Cutoff ('Cutoff Calculations') | E32: ='Cutoff Calculations'!E10 -> 4125 | G32: Turkey calculations
A33: Animals per farm | B33: Total farms | C33: Total animals | D33: Cumulative | E33: Cumulative % | G33: Farms larger than cutoff range | H33: =E36 -> 0.99786684 | J33: Citations
A34: 1 to 1999 | B34: 8640 | C34: 329960 | D34: =D35+C34 -> 285317097 | E34: =D34/$C$41 -> 1 | G34: Farms larger than and including cutoff range | H34: =E35 -> 0.99884353 | J34: =HYPERLINK("https://www.agcensus.usda.gov/Publications/2012/Full_Report/Volume_1,_Chapter_1_US/usv1.pdf","2012 Census of Agriculture") -> 2012 Census of Agriculture
A35: 2000 to 7999 | B35: 67 | C35: 278666 | D35: =D36+C35 -> 284987137 | E35: =D35/$C$41 -> 0.99884353 | G35: Percentile of cutoff in farm size range | H35: =(E32-2000)/(7999-2000) -> 0.3542257 | J35: =HYPERLINK("https://www3.epa.gov/npdes/pubs/sector_table.pdf","EPA CAFO definitions") -> EPA CAFO definitions
A36: 8000 to 15999 | B36: 97 | C36: 1143142 | D36: =D37+C36 -> 284708471 | E36: =D36/$C$41 -> 0.99786684 | G36: % of animals above cutoff | H36: =(H33-H34)*H35+H34 -> 0.99849756
A37: 16000 to 29999 | B37: 222 | C37: 5056778 | D37: =D38+C37 -> 283565329 | E37: =D37/$C$41 -> 0.99386028 | J37: Notes
A38: 30000 to 59999 | B38: 645 | C38: 28011500 | D38: =D39+C38 -> 278508551 | E38: =D38/$C$41 -> 0.97613692 | J38: This is a rough estimate based on the data we have available. We could not find any data on % of Small and Medium sized farms that meet the EPA criteria for CAFOs, so we took our best guess and hope to update it with hard evidence in the future.
A39: 60000 to 99999 | B39: 653 | C39: 49106441 | D39: =D40+C39 -> 250497051 | E39: =D39/$C$41 -> 0.87796018
A40: 100000 or more | B40: 830 | C40: 201390610 | D40: =D41+C40 -> 201390610 | E40: =D40/$C$41 -> 0.70584838
A41: Total sales | B41: 11154 | C41: =SUM(C34:C40) -> 285317097 | J41: Note that a CAFO as defined by the EPA and what the public would regard as a "factory farm" are not necessarily the same. For instance, a farm with 37,500 chickens or 3,000 pigs is only considered a CAFO if it meets certain conditions regarding surface water pollution, but farms of these sizes that don't meet these conditions could still house animals in ways that would be publicly regarded as crowded "factory" conditions.
...

Sheet Cutoff Calculations
A1: =HYPERLINK("https://www3.epa.gov/npdes/pubs/sector_table.pdf","Data on this sheet from EPA CAFO definitions") -> Data on this sheet from EPA CAFO definitions
A3: Cutoff for mammals | B3: 0.75
A4: Cutoff for birds | B4: 0.25
B6: Beef/veal cows | C6: Dairy cows | D6: Pigs | E6: Turkeys | F6: Egg-Laying Hens | G6: Meat Chickens
A7: Small-Medium | B7: 300 | C7: 200 | D7: 750 | E7: 16500 | F7: 9000 | G7: 37500
A8: Medium-Large | B8: 1000 | C8: 700 | D8: 2500 | E8: 55000 | F8: 30000 | G8: 125000
A9: Type | B9: Mammal | C9: Mammal | D9: Mammal | E9: Bird | F9: Bird | G9: Bird
A10: Cutoff | B10: =B7*B3 -> 225 | C10: =C7*B3 -> 150 | D10: =D7*B3 -> 562.5 | E10: =E7*B4 -> 4125 | F10: =F7*B4 -> 2250 | G10: =G7*B4 -> 9375

Sheet Fish Estimates
A1: =HYPERLINK("http://fishcount.org.uk/studydatascreens2/2015/numbers-of-farmed-fish-B0-2015.php?countrysort=United%2BStates%2Bof%2BAmerica","Greyed sheet contents sourced from: fishcount.org.uk, 'Estimated numbers of individuals in annual aquaculture production (FAO) of fish species,' US, 2015") -> Greyed sheet contents sourced from: fishcount.org.uk, 'Estimated numbers of individuals in annual aquaculture production (FAO) of fish species,' US, 2015
A2: Species | B2: Production (t) | C2: Estimated mean weight (EMW) (g) | D2: EMWid | E2: Generic Mean Weight (g) | F2: Estimated Numbers (millions)
A4: Channel catfish | B4: 143992 | C4: 340-680 | D4: 45 | F4: 212 - 424
A6: Rainbow trout | B6: 20799 | C6: 210-5,000 | D6: 155 | F6: 4 - 99
A8: Atlantic salmon | B8: 18719 | C8: 3,614-8,434 | D8: 21 | F8: 2 - 5
A10: Tilapias nei | B10: 8618 | C10: 250-800 | D10: 215 | F10: 11 - 34
A12: Striped bass, hybrid | B12: 3679 | C12: 816 | D12: 205 | F12: 5
A14: Red drum | B14: 1500 | C14: 1000 | D14: 156 | F14: 2
A16: Sturgeons nei | B16: 947 | E16: 322-1,081 | F16: 1 - 3
A18: Freshwater fishes nei | B18: 709 | E18: 322-1,081 | F18: 1 - 2
A20: Marine fishes nei | B20: 600 | E20: 322-1,081 | F20: 1 - 2
A22: Cyprinids nei | B22: 461 | E22: 322-1,081 | F22: <1 - 1
A24: Longfin yellowtail | B24: 400 | E24: 322-1,081 | F24: <1 - 1
A26: Barramundi(=Giant seaperch) | B26: 400 | C26: 300-2,000 | D26: 25 | F26: <1 - 1
A28: American yellow perch | B28: 100 | C28: 227 | D28: 7 | F28: <1
A32: Totals by estimate type:
B34: Production (t) | F34: Estimated Numbers (millions)
A36: Single species with an EMW | B36: 189189 | F36: 225 - 536
A38: Multi species with an EMW | B38: 8618 | F38: 11 - 34
A40: Totals for species with an EMW | B40: 197807 | F40: 236 - 570
A42: Totals for species without EMW | B42: 3117 | F42: 3 - 10
A44: Total fish production | B44: 200924 | F44: 238 - 580
A46: out of total aquaculture production | B46: 425973
A47: =HYPERLINK("https://www.getguesstimate.com/models/9916?token=k1KvmkB0E_IvYTut4bKxfMd9RHHcsuZfEGsZcCwp6MWyS5cfgVKppf9jOrICUlmisg7TzGqGvGn5jeqmeYljjQ","Greyed sheet contents sourced from: Animal Charity Evaluators,'Guesstimate Model of U.S. Per Capita Consumption of Farmed Finfish'") -> Greyed sheet contents sourced from: Animal Charity Evaluators,'Guesstimate Model of U.S. Per Capita Consumption of Farmed Finfish'
A48: =HYPERLINK("https://docs.getguesstimate.com/theory/monte_carlo_simulations.html","We are averaging across multiple page loads because the Monte Carlo estimation techniques Guesstimate uses to produce its distributions use a small sample size so as to load pages quickly. See more in their documentation.") -> We are averaging across multiple page loads because the Monte Carlo estimation techniques Guesstimate uses to produce its distributions use a small sample size so as to load pages quickly. See more in their documentation.
B49: Total farmed fish consumed anually per capita, minimum | C49: Total farmed fish consumed anually per capita, average | D49: Total farmed fish consumed anually per capita, maximum | E49: Average lifespan in months, minimum | F49: Average lifespan in months, average | G49: Average lifespan in months, maximum | H49: Farmed fish years required annually per capita (slaughtered fish), minimum | I49: Farmed fish years required annually per capita (slaughtered fish), average | J49: Farmed fish years required annually per capita (slaughtered fish), maximum | K49: Farmed fish years required annually per capita (total), minimum | L49: Farmed fish years required annually per capita (total), average | M49: Farmed fish years required annually per capita (total), maximum
A50: Salmon 1st Page Load | B50: 0.21 | C50: 0.29 | D50: 0.4 | E50: 18 | F50: 27 | G50: 36 | H50: 0.39 | I50: 0.65 | J50: 0.99 | K50: 0.42 | L50: 0.71 | M50: 1.1
A51: Salmon 2nd Page Load | B51: 0.21 | C51: 0.29 | D51: 0.39 | E51: 18 | F51: 27 | G51: 36 | H51: 0.39 | I51: 0.65 | J51: 0.98 | K51: 0.41 | L51: 0.7 | M51: 1.1
A52: Salmon 3rd Page Load | B52: 0.21 | C52: 0.29 | D52: 0.39 | E52: 18 | F52: 27 | G52: 36 | H52: 0.38 | I52: 0.65 | J52: 0.97 | K52: 0.41 | L52: 0.7 | M52: 1.1
A54: Tilapia 1st Page Load | B54: 1.9 | C54: 3.2 | D54: 5.3 | E54: 5.9 | F54: 8 | G54: 9.9 | H54: 1.2 | I54: 2.1 | J54: 3.7 | K54: 1.1 | L54: 2.2 | M54: 3.9
A55: Tilapia 2nd Page Load | B55: 1.9 | C55: 3.2 | D55: 5.2 | E55: 5.9 | F55: 8 | G55: 10 | H55: 1.1 | I55: 2.1 | J55: 3.6 | K55: 1.2 | L55: 2.2 | M55: 3.8
A56: Tilapia 3rd Page Load | B56: 1.8 | C56: 3.2 | D56: 5.1 | E56: 5.9 | F56: 8 | G56: 10 | H56: 1.1 | I56: 2.1 | J56: 3.6 | K56: 1.1 | L56: 2.2 | M56: 3.7
A58: Pangasius 1st Page Load | B58: 0.71 | C58: 1.2 | D58: 2.1 | E58: 8 | F58: 9.3 | G58: 10 | H58: 0.54 | I58: 0.92 | J58: 1.6 | K58: 0.56 | L58: 0.96 | M58: 1.7
A59: Pangasius 2nd Page Load | B59: 0.72 | C59: 1.2 | D59: 2.1 | E59: 9 | F59: 9.2 | G59: 10 | H59: 0.54 | I59: 0.91 | J59: 1.6 | K59: 0.56 | L59: 0.95 | M59: 1.7
A60: Pangasius 3rd Page Load | B60: 0.72 | C60: 1.2 | D60: 2.1 | E60: 8 | F60: 9.2 | G60: 10 | H60: 0.54 | I60: 0.94 | J60: 1.7 | K60: 0.56 | L60: 0.98 | M60: 1.8
A62: Catfish 1st Page Load | B62: 0.47 | C62: 0.86 | D62: 1.5 | E62: 15 | F62: 21 | G62: 27 | H62: 0.73 | I62: 1.5 | J62: 2.7 | K62: 0.8 | L62: 1.8 | M62: 3.2
A63: Catfish 2nd Page Load | B63: 0.48 | C63: 0.87 | D63: 1.5 | E63: 15 | F63: 21 | G63: 27 | H63: 0.74 | I63: 1.5 | J63: 2.7 | K63: 0.67 | L63: 1.2 | M63: 2.8
A64: Catfish 3rd Page Load | B64: 0.47 | C64: 0.86 | D64: 1.5 | E64: 15 | F64: 21 | G64: 27 | H64: 0.76 | I64: 1.5 | J64: 2.7 | K64: 0.79 | L64: 1.6 | M64: 3
A66: Salmon avg | B66: =SUM(B50:B52)/3 -> 0.21 | C66: =SUM(C50:C52)/3 -> 0.29 | D66: =SUM(D50:D52)/3 -> 0.39333333 | E66: =SUM(E50:E52)/3 -> 18 | F66: =SUM(F50:F52)/3 -> 27 | G66: =SUM(G50:G52)/3 -> 36 | H66: =SUM(H50:H52)/3 -> 0.38666667 | I66: =SUM(I50:I52)/3 -> 0.65 | ... M66: =SUM(M50:M52)/3 -> 1.1
A67: Tilapia avg | B67: =SUM(B54:B56)/3 -> 1.8666667 | C67: =SUM(C54:C56)/3 -> 3.2 | D67: =SUM(D54:D56)/3 -> 5.2 | E67: =SUM(E54:E56)/3 -> 5.9 | F67: =SUM(F54:F56)/3 -> 8 | G67: =SUM(G54:G56)/3 -> 9.9666667 | H67: =SUM(H54:H56)/3 -> 1.1333333 | I67: =SUM(I54:I56)/3 -> 2.1 | ... M67: =SUM(M54:M56)/3 -> 3.8
...
